Workbook

Sheet README
A1: The templates were generated using the FAIR eDNA checklist version of;
A2: FAIRe_checklist_v1.0.2.xlsx
A4: Date/Time generated;
A5: 2025-07-02T11:34:09+08:00
A7: Note: This template includes all data components and terms from the FAIR eDNA checklist, encompassing sections for both targeted assays and metabarcoding assay types.
A9: Requirement levels;
A10: M = Mandatory
A11: HR = Highly recommended
A12: R = Recommended
A13: O = Optional

Sheet projectMetadata
A1: requirement_level_code | B1: section | C1: term_name | D1: project_level
A2: M | B2: Project | C2: recordedBy | D2: C Cowgill
A3: R | B3: Project | C3: recordedByID | D3: https://orcid.org/0009-0005-1382-998X
A4: M | B4: Project | C4: project_contact | D4: c.cowgill@ucl.ac.uk
A5: R | B5: Project | C5: institution | D5: University of Hull
A6: R | B6: Project | C6: institutionID | D6: https://www.hull.ac.uk/
A7: R | B7: Project | C7: project_name | D7: Dundreggan functional diversity chronosequence
A8: M | B8: Project | C8: project_id | D8: CROP_2024
A9: O | B9: Project | C9: parent_project_id | D9: CCowgill_PhD
A10: O | B10: Project | C10: study_factor | D10: Species reintroduction | Integrating eDNA with cameras | eDNA detectability modelling
A11: M | B11: Project | C11: assay_type | D11: metabarcoding
A12: HR | B12: Project | C12: sterilise_method | D12: Sampling bottles were soaked in 10% bleach, then 5% lipsol, then double rinsed with sterilised water. Sample bottles were only handled with single use nitrile gloves and stored in a sterilised coolbag (wiped down with 10% bleach) during fieldwork.
... A15: M | B15: Data management | C15: checkls_ver | D15: 1.0.2
A16: R | B16: Data management | C16: mod_date | D16: 46145
A17: R | B17: Data management | C17: license
A18: R | B18: Data management | C18: rightsHolder | D18: University of Hull
A19: R | B19: Data management | C19: accessRights | D19: CC-BY 4.0
A20: O | B20: Data management | C20: informationWithheld
A21: O | B21: Data management | C21: dataGeneralizations
A22: R | B22: Data management | C22: bibliographicCitation
A23: O | B23: Data management | C23: associated_resource
A24: R | B24: Data management | C24: code_repo | D24: https://github.com/clarecowgill/Beaver-Otter-Detectability-eDNA-and-cameras
A25: R | B25: Sample collection | C25: biological_rep | D25: 10 (monthly analysis), 13 (spatial analysis)
A26: M | B26: PCR | C26: pcr_0_1 | D26: 1
A27: O | B27: PCR | C27: inhibition_check_0_1 | D27: 1
A28: O | B28: PCR | C28: inhibition_check | D28: All samples visually checked for inhibition with gel electrophoresis. Where inhibition was suspected, PCR was repeated with samples diluted with a 1:10 dilution.
A29: O | B29: PCR | C29: thermocycler | D29: Applied BiosystemsTM VeritiTM Thermal Cycler (Fisher Scientific, UK)
A30: M | B30: PCR | C30: assay_name | D30: 12S-V5
A31: R | B31: PCR | C31: assay_validation | D31: In-silico validation via a curated UK vertebrate 12S reference database and stringent BLAST assignment. In-situ validation using negative controls and species-specific LOD thresholds (mean + 3 SD), with additional filtering of low-abundance reads and removal of non-target/contaminant taxa.
A32: M | B32: PCR | C32: targetTaxonomicAssay | D32: vertebrates
A33: R | B33: PCR | C33: targetTaxonomicScope | D33: vertebrates
A34: HR | B34: PCR | C34: target_gene | D34: 12S rRNA (SSU mitochondria)
A35: O | B35: PCR | C35: target_subfragment | D35: V5
A36: HR | B36: PCR | C36: ampliconSize | D36: 106
A37: M | B37: PCR | C37: pcr_primer_forward | D37: ACTGGGATTAGATACCCC
A38: M | B38: PCR | C38: pcr_primer_reverse | D38: TAGAACAGGCTCCTCTAG
A39: R | B39: PCR | C39: pcr_primer_name_forward | D39: 12S-V5-F
A40: R | B40: PCR | C40: pcr_primer_name_reverse | D40: 12S-V5-R
A41: HR | B41: PCR | C41: pcr_primer_reference_forward | D41: 10.1093/nar/gkr732
A42: HR | B42: PCR | C42: pcr_primer_reference_reverse | D42: 10.1093/nar/gkr732
...

Sheet Drop-down values
A1: term_name | B1: term_type | C1: vocab_options | D1: n_options | E1: vocab1 | F1: vocab2 | G1: vocab3 | H1: vocab4 | I1: vocab5 | J1: vocab6 | K1: vocab7 | L1: vocab8 | M1: vocab9 | N1: vocab10 | O1: vocab11 | P1: vocab12 | Q1: vocab13 | R1: vocab14 | S1: vocab15 | T1: vocab16 | U1: vocab17 | V1: vocab18 | W1: vocab19 | X1: vocab20 | Y1: vocab21 | Z1: vocab22 | AA1: vocab23 | AB1: vocab24 | AC1: vocab25 | AD1: vocab26 | AE1: vocab27 | AF1: vocab28 | AG1: vocab29
A2: assay_type | B2: controlled vocabulary | C2: targeted | metabarcoding | other: | D2: 3 | E2: targeted | F2: metabarcoding | G2: other:
A3: neg_cont_0_1 | B3: Boolean | C3: 0 | 1 | D3: 2 | E3: 0 | F3: 1
A4: pos_cont_0_1 | B4: Boolean | C4: 0 | 1 | D4: 2 | E4: 0 | F4: 1
A5: samp_category | B5: controlled vocabulary | C5: sample | negative control | positive control | PCR standard | other: | D5: 5 | E5: sample | F5: negative control | G5: positive control | H5: PCR standard | I5: other:
A6: neg_cont_type | B6: controlled vocabulary | C6: site negative | field negative | process negative | extraction negative | PCR negative | other: | D6: 6 | E6: site negative | F6: field negative | G6: process negative | H6: extraction negative | I6: PCR negative | J6: other:
A7: verbatimCoordinateSystem | B7: controlled vocabulary | C7: decimal degrees | degrees minutes seconds | UTM | other: | D7: 4 | E7: decimal degrees | F7: degrees minutes seconds | G7: UTM | H7: other:
A8: verbatimSRS | B8: controlled vocabulary | C8: WGS84 | NAD84 | NAD27 | GDA94 | GDA2020 | ETRS89 | JGD2000 | other: | D8: 8 | E8: WGS84 | F8: NAD84 | G8: NAD27 | H8: GDA94 | I8: GDA2020 | J8: ETRS89 | K8: JGD2000 | L8: other:
A9: habitat_natural_artificial_0_1 | B9: Boolean | C9: 0 | 1 | D9: 2 | E9: 0 | F9: 1
A10: samp_size_unit | B10: controlled vocabulary | C10: mL | L | mg | g | kg | cm2 | m2 | cm3 | m3 | other: | D10: 10 | E10: mL | F10: L | G10: mg | H10: g | I10: kg | J10: cm2 | K10: m2 | L10: cm3 | M10: m3 | N10: other:
A11: samp_store_sol | B11: controlled vocabulary | C11: ethanol | sodium acetate | longmire | lysis buffer | none | other: | D11: 6 | E11: ethanol | F11: sodium acetate | G11: longmire | H11: lysis buffer | I11: none | J11: other:
A12: filter_passive_active_0_1 | B12: Boolean | C12: 0 | 1 | D12: 2 | E12: 0 | F12: 1
A13: pump_flow_rate_unit | B13: controlled vocabulary | C13: m3/s | m3/min | m3/h | L/s | L/min | L/h | other: | D13: 7 | E13: m3/s | F13: m3/min | G13: m3/h | H13: L/s | I13: L/min | J13: L/h | K13: other:
A14: filter_material | B14: controlled vocabulary | C14: cellulose | cellulose ester | glass fiber | thermoplastic membrane | track etched polycarbonate | nylon | polyethersulfone| other: | D14: 8 | E14: cellulose | F14: cellulose ester | G14: glass fiber | H14: thermoplastic membrane | I14: track etched polycarbonate | J14: nylon | K14: polyethersulfone | L14: other:
A15: precip_chem_prep | B15: controlled vocabulary | C15: ethanol | isopropanol | sodium chloride | other: | D15: 4 | E15: ethanol | F15: isopropanol | G15: sodium chloride | H15: other:
A16: prepped_samp_store_sol | B16: controlled vocabulary | C16: ethanol | sodium acetate | longmire | lysis buffer | none | other: | D16: 6 | E16: ethanol | F16: sodium acetate | G16: longmire | H16: lysis buffer | I16: none | J16: other:
A17: samp_vol_we_dna_ext_unit | B17: controlled vocabulary | C17: mL | L | mg | g | kg | cm2 | m2 | cm3 | m3 | other: | D17: 10 | E17: mL | F17: L | G17: mg | H17: g | I17: kg | J17: cm2 | K17: m2 | L17: cm3 | M17: m3 | N17: other:
A18: nucl_acid_ext_lysis | B18: controlled vocabulary | C18: physical | chemical | enzymatic | thermal | osmotic | other: | D18: 6 | E18: physical | F18: chemical | G18: enzymatic | H18: thermal | I18: osmotic | J18: other:
A19: nucl_acid_ext_sep | B19: controlled vocabulary | C19: column-based | magnetic beads | centrifugation | precipitation | phenol chloroform | gel electrophoresis | other: | D19: 7 | E19: column-based | F19: magnetic beads | G19: centrifugation | H19: precipitation | I19: phenol chloroform | J19: gel electrophoresis | K19: other:
A20: dna_cleanup_0_1 | B20: Boolean | C20: 0 | 1 | D20: 2 | E20: 0 | F20: 1
A21: concentration_unit | B21: controlled vocabulary | C21: ng/µl | copies/µl | other: | D21: 3 | E21: ng/µl | F21: copies/µl | G21: other:
A22: pcr_0_1 | B22: Boolean | C22: 0 | 1 | D22: 2 | E22: 0 | F22: 1
A23: inhibition_check_0_1 | B23: Boolean | C23: 0 | 1 | D23: 2 | E23: 0 | F23: 1
A24: target_gene | B24: controlled vocabulary | C24: 12S rRNA (SSU mitochondria) | 16S rRNA (LSU mitochondria) | 16S rRNA (SSU prokaryote) | 23S rRNA (LSU prokaryote) | 18S rRNA (SSU eukaryote) | 28S rRNA (LSU eukaryote) | rbcL | CytB | COI | COII | COIII | nifH | ITS | ND1 | ND2 | ND3 | ND4 | ND5 | ND6 | amoA | rpoB | rpoC1 | rpoC2 | matK | trnH | trnL | psbK | D-loop | other: | D24: 29 | E24: 12S rRNA (SSU mitochondria) | F24: 16S rRNA (LSU mitochondria) | G24: 16S rRNA (SSU prokaryote) | H24: 23S rRNA (LSU prokaryote) | I24: 18S rRNA (SSU eukaryote) | J24: 28S rRNA (LSU eukaryote) | K24: rbcL | L24: CytB | M24: COI | N24: COII | O24: COIII | P24: nifH | Q24: ITS | R24: ND1 | S24: ND2 | T24: ND3 | U24: ND4 | V24: ND5 | W24: ND6 | X24: amoA | Y24: rpoB | Z24: rpoC1 | AA24: rpoC2 | AB24: matK | AC24: trnH | AD24: trnL | AE24: psbK | AF24: D-loop | AG24: other:
A25: probeQuencher | B25: controlled vocabulary | C25: Zero-End Quencher (ZEN) | TAMRA | lowa Black | Minor Groove Binder (MGB) | Black Hole Quencher (BHQ) | other: | D25: 6 | E25: Zero-End Quencher (ZEN) | F25: TAMRA | G25: lowa Black | H25: Minor Groove Binder (MGB) | I25: Black Hole Quencher (BHQ) | J25: other:
A26: amp_vis_method | B26: controlled vocabulary | C26: qPCR | dPCR | gel electrophoresis | CE-PCR | LAMP | other: | D26: 6 | E26: qPCR | F26: dPCR | G26: gel electrophoresis | H26: CE-PCR | I26: LAMP | J26: other:
A27: pcr_assay_lod_unit | B27: controlled vocabulary | C27: copies/reaction | copies/µL | ng/reaction | ng/µL | other: | D27: 5 | E27: copies/reaction | F27: copies/µL | G27: ng/reaction | H27: ng/µL | I27: other:
A28: pcr_assay_loq_unit | B28: controlled vocabulary | C28: copies/reaction | copies/µL | ng/reaction | ng/µL | other: | D28: 5 | E28: copies/reaction | F28: copies/µL | G28: ng/reaction | H28: ng/µL | I28: other:
A29: std_type | B29: controlled vocabulary | C29: synthetic double-stranded DNA | plasmid | amplicon | gDNA | other: | D29: 5 | E29: synthetic double-stranded DNA | F29: plasmid | G29: amplicon | H29: gDNA | I29: other:
A30: automaticThresholdQuantificationCycle | B30: Boolean | C30: 0 | 1 | D30: 2 | E30: 0 | F30: 1
A31: automaticBaselineValue | B31: Boolean | C31: 0 | 1 | D31: 2 | E31: 0 | F31: 1
A32: std_conc_unit | B32: controlled vocabulary | C32: copies/reaction | copies/µL of DNA extract | copies/µL of reaction | ng/reaction | ng/µL of DNA extract | ng/µL of reaction | other: | D32: 7 | E32: copies/reaction | F32: copies/µL of DNA extract | G32: copies/µL of reaction | H32: ng/reaction | I32: ng/µL of DNA extract | J32: ng/µL of reaction | K32: other:
A33: estimatedNumberOfCopies_method | B33: controlled vocabulary | C33: Ct/Cq with standard curve | Ct/Cq with standard bionomial data | direct output from the PCR instrument used | gel fluorescence intensities | other: | D33: 5 | E33: Ct/Cq with standard curve | F33: Ct/Cq with standard bionomial data | G33: direct output from the PCR instrument used | H33: gel fluorescence intensities | I33: other:
A34: estimatedNumberOfCopies_unit | B34: controlled vocabulary | C34: copies/reaction | copies/µL of DNA extract | copies/µL of reaction | ng/reaction | ng/µL of DNA extract | ng/µL of reaction | other: | D34: 7 | E34: copies/reaction | F34: copies/µL of DNA extract | G34: copies/µL of reaction | H34: ng/reaction | I34: ng/µL of DNA extract | J34: ng/µL of reaction | K34: other:
A35: estimatedNumberOfCopies_error_type | B35: controlled vocabulary | C35: standard error | standard deviation | 95% confidence interval | other: | D35: 4 | E35: standard error | F35: standard deviation | G35: 95% confidence interval | H35: other:
A36: detected_notDetected | B36: Boolean | C36: 0 | 1 | D36: 2 | E36: 0 | F36: 1
A37: barcoding_pcr_appr | B37: controlled vocabulary | C37: one-step PCR | two-step PCR | ligation-based | other: | D37: 4 | E37: one-step PCR | F37: two-step PCR | G37: ligation-based | H37: other:
A38: platform | B38: controlled vocabulary | C38: ILLUMINA | BGISEQ | CAPILLARY | DNBSEQ | ELEMENT | GENAPSYS | GENEMIND | HELICOS | ION_TORRENT | LS454 | OXFORD_NANOPORE | PACBIO_SMRT | TAPESTRI | VELA_DIAGNOSTICS | ULTIMA | other: | D38: 16 | E38: ILLUMINA | F38: BGISEQ | G38: CAPILLARY | H38: DNBSEQ | I38: ELEMENT | J38: GENAPSYS | K38: GENEMIND | L38: HELICOS | M38: ION_TORRENT | N38: LS454 | O38: OXFORD_NANOPORE | P38: PACBIO_SMRT | Q38: TAPESTRI | R38: VELA_DIAGNOSTICS | S38: ULTIMA | T38: other:
A39: lib_layout | B39: controlled vocabulary | C39: paired end | single end | other: | D39: 3 | E39: paired end | F39: single end | G39: other:
A40: lib_conc_unit | B40: controlled vocabulary | C40: ng/µL | nM | pM | other: | D40: 4 | E40: ng/µL | F40: nM | G40: pM | H40: other:
...

Sheet sampleMetadata
A1: # requirement_level_code | B1: M | C1: M | D1: M | E1: R | F1: O | G1: O | H1: R | I1: O | J1: M | K1: M | L1: O | M1: O | N1: O | O1: O | P1: M | Q1: M | R1: O | S1: O | T1: O | U1: M | V1: M | W1: M | X1: R | Y1: R | Z1: R | AA1: HR | AB1: HR | AC1: HR | AD1: HR | AE1: HR | AF1: O | AG1: O | AH1: O | AI1: R | AJ1: R | AK1: R | AL1: O | AM1: O | AN1: O | AO1: HR | AP1: HR | AQ1: R | AR1: R | AS1: HR | AT1: R | AU1: HR | AV1: HR | AW1: HR | AX1: HR | AY1: R | AZ1: R | BA1: R | BB1: O | BC1: O | BD1: HR | BE1: HR | BF1: R | BG1: R | BH1: HR | BI1: HR | BJ1: R | BK1: R | BL1: R | BM1: R | BN1: R | BO1: O | BP1: O | BQ1: R | BR1: O | BS1: M | BT1: M | BU1: O | BV1: R | BW1: R | BX1: R | BY1: O | BZ1: O | CA1: O | CB1: O | CC1: O | CD1: O | CE1: O | CF1: O | CG1: O | CH1: O | CI1: O | CJ1: O | CK1: O | CL1: O | CM1: O | CN1: O | CO1: O | CP1: O | CQ1: O | CR1: O | CS1: O | CT1: O | CU1: O | CV1: O | CW1: O | CX1: O | CY1: O | CZ1: O | DA1: O | DB1: O | DC1: O | DD1: O | DE1: O | DF1: O | DG1: O | DH1: O | DI1: O | DJ1: O | DK1: O | DL1: O | DM1: O | DN1: O | DO1: O | DP1: O | DQ1: O | DR1: O | DS1: O | DT1: O | DU1: O | DV1: O | DW1: O | DX1: O | DY1: O | DZ1: O | EA1: O | EB1: O | EC1: O | ED1: O | EE1: O | EF1: O | EG1: O | EH1: O | EI1: O | EJ1: O | EK1: O | EL1: O
A2: # section | B2: Sample information | C2: Sample information | D2: Sample information | E2: Sample relations | F2: Sample relations | G2: Sample relations | H2: Sample relations | I2: Sample relations | J2: Sample collection | K2: Sample collection | L2: Sample collection | M2: Sample collection | N2: Sample collection | O2: Sample collection | P2: Sample collection | Q2: Sample collection | R2: Sample collection | S2: Sample collection | T2: Sample collection | U2: Sample collection | V2: Sample collection | W2: Sample collection | X2: Sample collection | Y2: Sample collection | Z2: Sample collection | AA2: Sample collection | AB2: Sample collection | AC2: Sample storage | AD2: Sample storage | AE2: Sample storage | AF2: Sample storage | AG2: Sample storage | AH2: Sample storage | AI2: Sample preparation | AJ2: Sample preparation | AK2: Sample preparation | AL2: Sample preparation | AM2: Sample preparation | AN2: Sample preparation | AO2: Sample preparation | AP2: Sample preparation | AQ2: Sample preparation | AR2: Sample preparation | AS2: Sample preparation | AT2: Sample preparation | AU2: Sample preparation | AV2: Sample preparation | AW2: Sample preparation | AX2: Sample preparation | AY2: Sample preparation | AZ2: Sample preparation | BA2: Sample preparation | BB2: Sample preparation | BC2: Nucleic acid extraction | BD2: Nucleic acid extraction | BE2: Nucleic acid extraction | BF2: Nucleic acid extraction | BG2: Nucleic acid extraction | BH2: Nucleic acid extraction | BI2: Nucleic acid extraction | BJ2: Nucleic acid extraction | BK2: Nucleic acid extraction | BL2: Nucleic acid extraction | BM2: Nucleic acid extraction | BN2: Nucleic acid extraction | BO2: Nucleic acid extraction | BP2: Nucleic acid extraction | BQ2: Nucleic acid extraction | BR2: Nucleic acid extraction | BS2: PCR | BT2: Targeted assay detection | BU2: Environment | BV2: Environment | BW2: Environment | BX2: Environment | BY2: Environment | BZ2: Environment | CA2: Environment | CB2: Environment | CC2: Environment | CD2: Environment | CE2: Environment | CF2: Environment | CG2: Environment | CH2: Environment | CI2: Environment | CJ2: Environment | CK2: Environment | CL2: Environment | CM2: Environment | CN2: Environment | CO2: Environment | CP2: Environment | CQ2: Environment | CR2: Environment | CS2: Environment | CT2: Environment | CU2: Environment | CV2: Environment | CW2: Environment | CX2: Environment | CY2: Environment | CZ2: Environment | DA2: Environment | DB2: Environment | DC2: Environment | DD2: Environment | DE2: Environment | DF2: Environment | DG2: Environment | DH2: Environment | DI2: Environment | DJ2: Environment | DK2: Environment | DL2: Environment | DM2: Environment | DN2: Environment | DO2: Environment | DP2: Environment | DQ2: Environment | DR2: Environment | DS2: Environment | DT2: Environment | DU2: Environment | DV2: Environment | DW2: Environment | DX2: Environment | DY2: Environment | DZ2: Environment | EA2: Environment | EB2: Environment | EC2: Environment | ED2: Environment | EE2: Environment | EF2: Environment | EG2: Environment | EH2: Environment | EI2: Environment | EJ2: Environment | EK2: Environment | EL2: Environment
A3: samp_name | B3: samp_category | C3: neg_cont_type | D3: pos_cont_type | E3: materialSampleID | F3: sample_derived_from | G3: sample_composed_of | H3: rel_cont_id | I3: biological_rep_relation | J3: decimalLongitude | K3: decimalLatitude | L3: verbatimLongitude | M3: verbatimLatitude | N3: verbatimCoordinateSystem | O3: verbatimSRS | P3: geo_loc_name | Q3: eventDate | R3: eventDurationValue | S3: verbatimEventDate | T3: verbatimEventTime | U3: env_broad_scale | V3: env_local_scale | W3: env_medium | X3: habitat_natural_artificial_0_1 | Y3: samp_collect_method | Z3: samp_collect_device | AA3: samp_size | AB3: samp_size_unit | AC3: samp_store_temp | AD3: samp_store_sol | AE3: samp_store_dur | AF3: samp_store_loc | AG3: dna_store_loc | AH3: samp_store_method_additional | AI3: samp_mat_process | AJ3: filter_passive_active_0_1 | AK3: stationed_sample_dur | AL3: pump_flow_rate | AM3: pump_flow_rate_unit | AN3: prefilter_material | AO3: size_frac_low | AP3: size_frac | AQ3: filter_diameter | AR3: filter_surface_area | AS3: filter_material | AT3: filter_name | AU3: precip_chem_prep | AV3: precip_force_prep | AW3: precip_time_prep | AX3: precip_temp_prep | AY3: prepped_samp_store_temp | AZ3: prepped_samp_store_sol | BA3: prepped_samp_store_dur | BB3: prep_method_additional | BC3: date_ext | BD3: samp_vol_we_dna_ext | BE3: samp_vol_we_dna_ext_unit | BF3: nucl_acid_ext_lysis | BG3: nucl_acid_ext_sep | BH3: nucl_acid_ext | BI3: nucl_acid_ext_kit | BJ3: nucl_acid_ext_modify | BK3: dna_cleanup_0_1 | BL3: dna_cleanup_method | BM3: concentration | BN3: concentration_unit | BO3: concentration_method | BP3: ratioOfAbsorbance260_280 | BQ3: pool_dna_num | BR3: nucl_acid_ext_method_additional | BS3: assay_name | BT3: detected_notDetected | BU3: samp_weather | BV3: minimumDepthInMeters | BW3: maximumDepthInMeters | BX3: tot_depth_water_col | BY3: elev | BZ3: alt | CA3: temp | CB3: chlorophyll | CC3: light_intensity | CD3: ph | CE3: ph_meth | CF3: salinity | CG3: suspend_part_matter | CH3: tidal_stage | CI3: turbidity | CJ3: water_current | CK3: humidity | CL3: solar_irradiance | CM3: wind_direction | CN3: wind_speed | CO3: host_species | CP3: host_life_stage | CQ3: host_tot_mass | CR3: host_tot_mass_unit | CS3: host_height | CT3: host_height_unit | CU3: host_length | CV3: host_length_unit | CW3: diss_inorg_carb | CX3: diss_inorg_carb_unit | CY3: diss_inorg_nitro | CZ3: diss_inorg_nitro_unit | DA3: diss_org_carb | DB3: diss_org_carb_unit | DC3: diss_org_nitro | DD3: diss_org_nitro_unit | DE3: diss_oxygen | DF3: diss_oxygen_unit | DG3: tot_diss_nitro | DH3: tot_diss_nitro_unit | DI3: tot_inorg_nitro | DJ3: tot_inorg_nitro_unit | DK3: tot_nitro | DL3: tot_nitro_unit | DM3: tot_part_carb | DN3: tot_part_carb_unit | DO3: tot_org_carb | DP3: tot_org_carb_unit | DQ3: tot_org_c_meth | DR3: tot_nitro_content | DS3: tot_nitro_content_unit | DT3: tot_nitro_cont_meth | DU3: tot_carb | DV3: tot_carb_unit | DW3: part_org_carb | DX3: part_org_carb_unit | DY3: part_org_nitro | DZ3: part_org_nitro_unit | EA3: nitrate | EB3: nitrate_unit | EC3: nitrite | ED3: nitrite_unit | EE3: nitro | EF3: nitro_unit | EG3: org_carb | EH3: org_carb_unit | EI3: org_matter | EJ3: org_matter_unit | EK3: org_nitro | EL3: org_nitro_unit
A4: 0101 | B4: sample | E4: =_xlfn.CONCAT(projectMetadata!$D$8,"_",sampleMetadata!A4) -> CROP_2024_0101 | F4: =LEFT(A4,9) -> 0101 | G4: =F4 -> 0101 | H4: CROP_01EB, CROP_01FB, NEG01, POS01 | J4: -0.81100264 | K4: 54.305806 | P4: United Kingdom, Cropton | Q4: 45306.611 | R4: PT2M | U4: freshwater wetland ecosystem [ENVO_00000243] | V4: shrub layer [ENVO:01000336] | W4: fresh water [ENVO:00002011] | X4: 0 | Y4: Water sample (2L bottle dippled into small stream in 3 distinct areas within 3m of the point) | Z4: water bottle | AA4: 2000 | AB4: mL | AC4: 10 | AD4: none | AE4: PT3H | AP4: 0.45 | AS4: cellulose ester | AT4: Whatman | AY4: -18 | BF4: enzymatic | BG4: column-based | BH4: https://mbmg.pensoft.net/article/24556/ | BI4: Mu DNA | BJ4: https://mbmg.pensoft.net/article/24556/ | BK4: 0 | BQ4: 1 | BS4: 12S-V5
A5: 0102 | B5: sample | E5: =_xlfn.CONCAT(projectMetadata!$D$8,"_",sampleMetadata!A5) -> CROP_2024_0102 | F5: =LEFT(A5,9) -> 0102 | G5: =F5 -> 0102 | H5: CROP_01EB, CROP_01FB, NEG01, POS01 | J5: -0.80960976 | K5: 54.306325 | P5: United Kingdom, Cropton | Q5: 45306.601 | R5: PT2M | U5: freshwater wetland ecosystem [ENVO_00000243] | V5: shrub layer [ENVO:01000336] | W5: fresh water [ENVO:00002011] | X5: 0 | Y5: Water sample (2L bottle dippled into small stream in 3 distinct areas within 3m of the point) | Z5: water bottle | AA5: 2000 | AB5: mL | AC5: 10 | AD5: none | AE5: PT3H | AP5: 0.45 | AS5: cellulose ester | AT5: Whatman | AY5: -18 | BF5: enzymatic | BG5: column-based | BH5: https://mbmg.pensoft.net/article/24556/ | BI5: Mu DNA | BJ5: https://mbmg.pensoft.net/article/24556/ | BK5: 0 | BQ5: 1 | BS5: 12S-V5
A6: 0103 | B6: sample | E6: =_xlfn.CONCAT(projectMetadata!$D$8,"_",sampleMetadata!A6) -> CROP_2024_0103 | F6: =LEFT(A6,9) -> 0103 | G6: =F6 -> 0103 | H6: CROP_01EB, CROP_01FB, NEG01, POS01 | J6: -0.81187299 | K6: 54.305987 | P6: United Kingdom, Cropton | Q6: 45306.594 | R6: PT2M | U6: freshwater wetland ecosystem [ENVO_00000243] | V6: shrub layer [ENVO:01000336] | W6: fresh water [ENVO:00002011] | X6: 0 | Y6: Water sample (2L bottle dippled into small stream in 3 distinct areas within 3m of the point) | Z6: water bottle | AA6: 2000 | AB6: mL | AC6: 10 | AD6: none | AE6: PT3H | AP6: 0.45 | AS6: cellulose ester | AT6: Whatman | AY6: -18 | BF6: enzymatic | BG6: column-based | BH6: https://mbmg.pensoft.net/article/24556/ | BI6: Mu DNA | BJ6: https://mbmg.pensoft.net/article/24556/ | BK6: 0 | BQ6: 1 | BS6: 12S-V5
A7: 0104 | B7: sample | E7: =_xlfn.CONCAT(projectMetadata!$D$8,"_",sampleMetadata!A7) -> CROP_2024_0104 | F7: =LEFT(A7,9) -> 0104 | G7: =F7 -> 0104 | H7: CROP_01EB, CROP_01FB, NEG01, POS01 | J7: -0.8115562 | K7: 54.305646 | P7: United Kingdom, Cropton | Q7: 45306.583 | R7: PT2M | U7: freshwater wetland ecosystem [ENVO_00000243] | V7: shrub layer [ENVO:01000336] | W7: fresh water [ENVO:00002011] | X7: 0 | Y7: Water sample (2L bottle dippled into small stream in 3 distinct areas within 3m of the point) | Z7: water bottle | AA7: 2000 | AB7: mL | AC7: 10 | AD7: none | AE7: PT3H | AP7: 0.45 | AS7: cellulose ester | AT7: Whatman | AY7: -18 | BF7: enzymatic | BG7: column-based | BH7: https://mbmg.pensoft.net/article/24556/ | BI7: Mu DNA | BJ7: https://mbmg.pensoft.net/article/24556/ | BK7: 0 | BQ7: 1 | BS7: 12S-V5
A8: 0105 | B8: sample | E8: =_xlfn.CONCAT(projectMetadata!$D$8,"_",sampleMetadata!A8) -> CROP_2024_0105 | F8: =LEFT(A8,9) -> 0105 | G8: =F8 -> 0105 | H8: CROP_01EB, CROP_01FB, NEG01, POS01 | J8: -0.81322506 | K8: 54.30521 | P8: United Kingdom, Cropton | Q8: 45306.573 | R8: PT2M | U8: freshwater wetland ecosystem [ENVO_00000243] | V8: shrub layer [ENVO:01000336] | W8: fresh water [ENVO:00002011] | X8: 0 | Y8: Water sample (2L bottle dippled into small stream in 3 distinct areas within 3m of the point) | Z8: water bottle | AA8: 2000 | AB8: mL | AC8: 10 | AD8: none | AE8: PT3H | AP8: 0.45 | AS8: cellulose ester | AT8: Whatman | AY8: -18 | BF8: enzymatic | BG8: column-based | BH8: https://mbmg.pensoft.net/article/24556/ | BI8: Mu DNA | BJ8: https://mbmg.pensoft.net/article/24556/ | BK8: 0 | BQ8: 1 | BS8: 12S-V5
A9: 0106 | B9: sample | E9: =_xlfn.CONCAT(projectMetadata!$D$8,"_",sampleMetadata!A9) -> CROP_2024_0106 | F9: =LEFT(A9,9) -> 0106 | G9: =F9 -> 0106 | H9: CROP_01EB, CROP_01FB, NEG01, POS01 | J9: -0.81573976 | K9: 54.304996 | P9: United Kingdom, Cropton | Q9: 45306.562 | R9: PT2M | U9: freshwater wetland ecosystem [ENVO_00000243] | V9: shrub layer [ENVO:01000336] | W9: fresh water [ENVO:00002011] | X9: 0 | Y9: Water sample (2L bottle dippled into small stream in 3 distinct areas within 3m of the point) | Z9: water bottle | AA9: 2000 | AB9: mL | AC9: 10 | AD9: none | AE9: PT3H | AP9: 0.45 | AS9: cellulose ester | AT9: Whatman | AY9: -18 | BF9: enzymatic | BG9: column-based | BH9: https://mbmg.pensoft.net/article/24556/ | BI9: Mu DNA | BJ9: https://mbmg.pensoft.net/article/24556/ | BK9: 0 | BQ9: 1 | BS9: 12S-V5 | BU9: Moist, overcast
A10: 0107 | B10: sample | E10: =_xlfn.CONCAT(projectMetadata!$D$8,"_",sampleMetadata!A10) -> CROP_2024_0107 | F10: =LEFT(A10,9) -> 0107 | G10: =F10 -> 0107 | H10: CROP_01EB, CROP_01FB, NEG01, POS01 | J10: -0.81746413 | K10: 54.304684 | P10: United Kingdom, Cropton | Q10: 45306.552 | R10: PT2M | U10: freshwater wetland ecosystem [ENVO_00000243] | V10: shrub layer [ENVO:01000336] | W10: fresh water [ENVO:00002011] | X10: 0 | Y10: Water sample (2L bottle dippled into small stream in 3 distinct areas within 3m of the point) | Z10: water bottle | AA10: 2000 | AB10: mL | AC10: 10 | AD10: none | AE10: PT3H | AP10: 0.45 | AS10: cellulose ester | AT10: Whatman | AY10: -18 | BF10: enzymatic | BG10: column-based | BH10: https://mbmg.pensoft.net/article/24556/ | BI10: Mu DNA | BJ10: https://mbmg.pensoft.net/article/24556/ | BK10: 0 | BQ10: 1 | BS10: 12S-V5 | BU10: Dry, cloudy
A11: 0108 | B11: sample | E11: =_xlfn.CONCAT(projectMetadata!$D$8,"_",sampleMetadata!A11) -> CROP_2024_0108 | F11: =LEFT(A11,9) -> 0108 | G11: =F11 -> 0108 | H11: CROP_01EB, CROP_01FB, NEG01, POS01 | J11: -0.81789849 | K11: 54.304594 | P11: United Kingdom, Cropton | Q11: 45306.549 | R11: PT2M | U11: freshwater wetland ecosystem [ENVO_00000243] | V11: shrub layer [ENVO:01000336] | W11: fresh water [ENVO:00002011] | X11: 0 | Y11: Water sample (2L bottle dippled into small stream in 3 distinct areas within 3m of the point) | Z11: water bottle | AA11: 2000 | AB11: mL | AC11: 10 | AD11: none | AE11: PT3H | AP11: 0.45 | AS11: cellulose ester | AT11: Whatman | AY11: -18 | BF11: enzymatic | BG11: column-based | BH11: https://mbmg.pensoft.net/article/24556/ | BI11: Mu DNA | BJ11: https://mbmg.pensoft.net/article/24556/ | BK11: 0 | BQ11: 1 | BS11: 12S-V5 | BU11: Dry, cloudy
A12: 0109 | B12: sample | E12: =_xlfn.CONCAT(projectMetadata!$D$8,"_",sampleMetadata!A12) -> CROP_2024_0109 | F12: =LEFT(A12,9) -> 0109 | G12: =F12 -> 0109 | H12: CROP_01EB, CROP_01FB, NEG01, POS01 | J12: -0.81844389 | K12: 54.30436 | P12: United Kingdom, Cropton | Q12: 45306.538 | R12: PT2M | U12: freshwater wetland ecosystem [ENVO_00000243] | V12: shrub layer [ENVO:01000336] | W12: fresh water [ENVO:00002011] | X12: 0 | Y12: Water sample (2L bottle dippled into small stream in 3 distinct areas within 3m of the point) | Z12: water bottle | AA12: 2000 | AB12: mL | AC12: 10 | AD12: none | AE12: PT3H | AP12: 0.45 | AS12: cellulose ester | AT12: Whatman | AY12: -18 | BF12: enzymatic | BG12: column-based | BH12: https://mbmg.pensoft.net/article/24556/ | BI12: Mu DNA | BJ12: https://mbmg.pensoft.net/article/24556/ | BK12: 0 | BQ12: 1 | BS12: 12S-V5 | BU12: Dry, cloudy
A13: 0110 | B13: sample | E13: =_xlfn.CONCAT(projectMetadata!$D$8,"_",sampleMetadata!A13) -> CROP_2024_0110 | F13: =LEFT(A13,9) -> 0110 | G13: =F13 -> 0110 | H13: CROP_01EB, CROP_01FB, NEG01, POS01 | J13: -0.81895989 | K13: 54.304236 | P13: United Kingdom, Cropton | Q13: 45306.528 | R13: PT2M | U13: freshwater wetland ecosystem [ENVO_00000243] | V13: shrub layer [ENVO:01000336] | W13: fresh water [ENVO:00002011] | X13: 0 | Y13: Water sample (2L bottle dippled into small stream in 3 distinct areas within 3m of the point) | Z13: water bottle | AA13: 2000 | AB13: mL | AC13: 10 | AD13: none | AE13: PT3H | AP13: 0.45 | AS13: cellulose ester | AT13: Whatman | AY13: -18 | BF13: enzymatic | BG13: column-based | BH13: https://mbmg.pensoft.net/article/24556/ | BI13: Mu DNA | BJ13: https://mbmg.pensoft.net/article/24556/ | BK13: 0 | BQ13: 1 | BS13: 12S-V5 | BU13: Dry, cloudy
A14: 01EB | B14: negative control | C14: extraction negative | E14: =_xlfn.CONCAT(projectMetadata!$D$8,"_",sampleMetadata!A14) -> CROP_2024_01EB | F14: =LEFT(A14,9) -> 01EB | G14: =F14 -> 01EB | BF14: enzymatic | BG14: column-based | BH14: https://mbmg.pensoft.net/article/24556/ | BI14: Mu DNA | BJ14: https://mbmg.pensoft.net/article/24556/ | BK14: 0 | BQ14: 1 | BS14: 12S-V5 | BU14: Dry, cloudy
A15: 01FB | B15: negative control | C15: field negative | E15: =_xlfn.CONCAT(projectMetadata!$D$8,"_",sampleMetadata!A15) -> CROP_2024_01FB | F15: =LEFT(A15,9) -> 01FB | G15: =F15 -> 01FB | AP15: 0.45 | AS15: cellulose ester | AT15: Whatman | AY15: -18 | BF15: enzymatic | BG15: column-based | BH15: https://mbmg.pensoft.net/article/24556/ | BI15: Mu DNA | BJ15: https://mbmg.pensoft.net/article/24556/ | BK15: 0 | BQ15: 1 | BS15: 12S-V5 | BU15: Dry, cloudy
A16: 0201 | B16: sample | E16: =_xlfn.CONCAT(projectMetadata!$D$8,"_",sampleMetadata!A16) -> CROP_2024_0201 | F16: =LEFT(A16,9) -> 0201 | G16: =F16 -> 0201 | H16: CROP_02EB, CROP_02FB, NEG01, POS01 | J16: -0.81100264 | K16: 54.305806 | P16: United Kingdom, Cropton | Q16: 45336.708 | R16: PT2M | U16: freshwater wetland ecosystem [ENVO_00000243] | V16: shrub layer [ENVO:01000336] | W16: fresh water [ENVO:00002011] | X16: 0 | Y16: Water sample (2L bottle dippled into small stream in 3 distinct areas within 3m of the point) | Z16: water bottle | AA16: 2000 | AB16: mL | AC16: 10 | AD16: none | AE16: PT3H | AP16: 0.45 | AS16: cellulose ester | AT16: Whatman | AY16: -18 | BF16: enzymatic | BG16: column-based | BH16: https://mbmg.pensoft.net/article/24556/ | BI16: Mu DNA | BJ16: https://mbmg.pensoft.net/article/24556/ | BK16: 0 | BQ16: 1 | BS16: 12S-V5 | BU16: Dry, cloudy
A17: 0202 | B17: sample | E17: =_xlfn.CONCAT(projectMetadata!$D$8,"_",sampleMetadata!A17) -> CROP_2024_0202 | F17: =LEFT(A17,9) -> 0202 | G17: =F17 -> 0202 | H17: CROP_02EB, CROP_02FB, NEG01, POS01 | J17: -0.80960976 | K17: 54.306325 | P17: United Kingdom, Cropton | Q17: 45336.698 | R17: PT2M | U17: freshwater wetland ecosystem [ENVO_00000243] | V17: shrub layer [ENVO:01000336] | W17: fresh water [ENVO:00002011] | X17: 0 | Y17: Water sample (2L bottle dippled into small stream in 3 distinct areas within 3m of the point) | Z17: water bottle | AA17: 2000 | AB17: mL | AC17: 10 | AD17: none | AE17: PT3H | AP17: 0.45 | AS17: cellulose ester | AT17: Whatman | AY17: -18 | BF17: enzymatic | BG17: column-based | BH17: https://mbmg.pensoft.net/article/24556/ | BI17: Mu DNA | BJ17: https://mbmg.pensoft.net/article/24556/ | BK17: 0 | BQ17: 1 | BS17: 12S-V5 | BU17: Dry, cloudy
A18: 0203 | B18: sample | E18: =_xlfn.CONCAT(projectMetadata!$D$8,"_",sampleMetadata!A18) -> CROP_2024_0203 | F18: =LEFT(A18,9) -> 0203 | G18: =F18 -> 0203 | H18: CROP_02EB, CROP_02FB, NEG01, POS01 | J18: -0.81187299 | K18: 54.305987 | P18: United Kingdom, Cropton | Q18: 45336.688 | R18: PT2M | U18: freshwater wetland ecosystem [ENVO_00000243] | V18: shrub layer [ENVO:01000336] | W18: fresh water [ENVO:00002011] | X18: 0 | Y18: Water sample (2L bottle dippled into small stream in 3 distinct areas within 3m of the point) | Z18: water bottle | AA18: 2000 | AB18: mL | AC18: 10 | AD18: none | AE18: PT3H | AP18: 0.45 | AS18: cellulose ester | AT18: Whatman | AY18: -18 | BF18: enzymatic | BG18: column-based | BH18: https://mbmg.pensoft.net/article/24556/ | BI18: Mu DNA | BJ18: https://mbmg.pensoft.net/article/24556/ | BK18: 0 | BQ18: 1 | BS18: 12S-V5 | BU18: Dry, cloudy
A19: 0204 | B19: sample | E19: =_xlfn.CONCAT(projectMetadata!$D$8,"_",sampleMetadata!A19) -> CROP_2024_0204 | F19: =LEFT(A19,9) -> 0204 | G19: =F19 -> 0204 | H19: CROP_02EB, CROP_02FB, NEG01, POS01 | J19: -0.8115562 | K19: 54.305646 | P19: United Kingdom, Cropton | Q19: 45336.681 | R19: PT2M | U19: freshwater wetland ecosystem [ENVO_00000243] | V19: shrub layer [ENVO:01000336] | W19: fresh water [ENVO:00002011] | X19: 0 | Y19: Water sample (2L bottle dippled into small stream in 3 distinct areas within 3m of the point) | Z19: water bottle | AA19: 2000 | AB19: mL | AC19: 10 | AD19: none | AE19: PT3H | AP19: 0.45 | AS19: cellulose ester | AT19: Whatman | AY19: -18 | BF19: enzymatic | BG19: column-based | BH19: https://mbmg.pensoft.net/article/24556/ | BI19: Mu DNA | BJ19: https://mbmg.pensoft.net/article/24556/ | BK19: 0 | BQ19: 1 | BS19: 12S-V5 | BU19: Dry, cloudy
A20: 0205 | B20: sample | E20: =_xlfn.CONCAT(projectMetadata!$D$8,"_",sampleMetadata!A20) -> CROP_2024_0205 | F20: =LEFT(A20,9) -> 0205 | G20: =F20 -> 0205 | H20: CROP_02EB, CROP_02FB, NEG05, POS05 | J20: -0.81322506 | K20: 54.30521 | P20: United Kingdom, Cropton | Q20: 45336.667 | R20: PT2M | U20: freshwater wetland ecosystem [ENVO_00000243] | V20: shrub layer [ENVO:01000336] | W20: fresh water [ENVO:00002011] | X20: 0 | Y20: Water sample (2L bottle dippled into small stream in 3 distinct areas within 3m of the point) | Z20: water bottle | AA20: 2000 | AB20: mL | AC20: 10 | AD20: none | AE20: PT3H | AP20: 0.45 | AS20: cellulose ester | AT20: Whatman | AY20: -18 | BF20: enzymatic | BG20: column-based | BH20: https://mbmg.pensoft.net/article/24556/ | BI20: Mu DNA | BJ20: https://mbmg.pensoft.net/article/24556/ | BK20: 0 | BQ20: 1 | BS20: 12S-V5 | BU20: Dry, cloudy
A21: 0206 | B21: sample | E21: =_xlfn.CONCAT(projectMetadata!$D$8,"_",sampleMetadata!A21) -> CROP_2024_0206 | F21: =LEFT(A21,9) -> 0206 | G21: =F21 -> 0206 | H21: CROP_02EB, CROP_02FB, NEG05, POS05 | J21: -0.81573976 | K21: 54.304996 | P21: United Kingdom, Cropton | Q21: 45336.66 | R21: PT2M | U21: freshwater wetland ecosystem [ENVO_00000243] | V21: shrub layer [ENVO:01000336] | W21: fresh water [ENVO:00002011] | X21: 0 | Y21: Water sample (2L bottle dippled into small stream in 3 distinct areas within 3m of the point) | Z21: water bottle | AA21: 2000 | AB21: mL | AC21: 10 | AD21: none | AE21: PT3H | AP21: 0.45 | AS21: cellulose ester | AT21: Whatman | AY21: -18 | BF21: enzymatic | BG21: column-based | BH21: https://mbmg.pensoft.net/article/24556/ | BI21: Mu DNA | BJ21: https://mbmg.pensoft.net/article/24556/ | BK21: 0 | BQ21: 1 | BS21: 12S-V5 | BU21: Dry, cloudy
A22: 0207 | B22: sample | E22: =_xlfn.CONCAT(projectMetadata!$D$8,"_",sampleMetadata!A22) -> CROP_2024_0207 | F22: =LEFT(A22,9) -> 0207 | G22: =F22 -> 0207 | H22: CROP_02EB, CROP_02FB, NEG01, POS01 | J22: -0.81746413 | K22: 54.304684 | P22: United Kingdom, Cropton | Q22: 45336.646 | R22: PT2M | U22: freshwater wetland ecosystem [ENVO_00000243] | V22: shrub layer [ENVO:01000336] | W22: fresh water [ENVO:00002011] | X22: 0 | Y22: Water sample (2L bottle dippled into small stream in 3 distinct areas within 3m of the point) | Z22: water bottle | AA22: 2000 | AB22: mL | AC22: 10 | AD22: none | AE22: PT3H | AP22: 0.45 | AS22: cellulose ester | AT22: Whatman | AY22: -18 | BF22: enzymatic | BG22: column-based | BH22: https://mbmg.pensoft.net/article/24556/ | BI22: Mu DNA | BJ22: https://mbmg.pensoft.net/article/24556/ | BK22: 0 | BQ22: 1 | BS22: 12S-V5 | BU22: Dry, cloudy
A23: 0208 | B23: sample | E23: =_xlfn.CONCAT(projectMetadata!$D$8,"_",sampleMetadata!A23) -> CROP_2024_0208 | F23: =LEFT(A23,9) -> 0208 | G23: =F23 -> 0208 | H23: CROP_02EB, CROP_02FB, NEG01, POS01 | J23: -0.81789849 | K23: 54.304594 | P23: United Kingdom, Cropton | Q23: 45336.639 | R23: PT2M | U23: freshwater wetland ecosystem [ENVO_00000243] | V23: shrub layer [ENVO:01000336] | W23: fresh water [ENVO:00002011] | X23: 0 | Y23: Water sample (2L bottle dippled into small stream in 3 distinct areas within 3m of the point) | Z23: water bottle | AA23: 2000 | AB23: mL | AC23: 10 | AD23: none | AE23: PT3H | AP23: 0.45 | AS23: cellulose ester | AT23: Whatman | AY23: -18 | BF23: enzymatic | BG23: column-based | BH23: https://mbmg.pensoft.net/article/24556/ | BI23: Mu DNA | BJ23: https://mbmg.pensoft.net/article/24556/ | BK23: 0 | BQ23: 1 | BS23: 12S-V5 | BU23: Dry, cloudy
A24: 0209 | B24: sample | E24: =_xlfn.CONCAT(projectMetadata!$D$8,"_",sampleMetadata!A24) -> CROP_2024_0209 | F24: =LEFT(A24,9) -> 0209 | G24: =F24 -> 0209 | H24: CROP_02EB, CROP_02FB, NEG01, POS01 | J24: -0.81844389 | K24: 54.30436 | P24: United Kingdom, Cropton | Q24: 45336.625 | R24: PT2M | U24: freshwater wetland ecosystem [ENVO_00000243] | V24: shrub layer [ENVO:01000336] | W24: fresh water [ENVO:00002011] | X24: 0 | Y24: Water sample (2L bottle dippled into small stream in 3 distinct areas within 3m of the point) | Z24: water bottle | AA24: 2000 | AB24: mL | AC24: 10 | AD24: none | AE24: PT3H | AP24: 0.45 | AS24: cellulose ester | AT24: Whatman | AY24: -18 | BF24: enzymatic | BG24: column-based | BH24: https://mbmg.pensoft.net/article/24556/ | BI24: Mu DNA | BJ24: https://mbmg.pensoft.net/article/24556/ | BK24: 0 | BQ24: 1 | BS24: 12S-V5 | BU24: Dry, cloudy
A25: 0210 | B25: sample | E25: =_xlfn.CONCAT(projectMetadata!$D$8,"_",sampleMetadata!A25) -> CROP_2024_0210 | F25: =LEFT(A25,9) -> 0210 | G25: =F25 -> 0210 | H25: CROP_02EB, CROP_02FB, NEG01, POS01 | J25: -0.81895989 | K25: 54.304236 | P25: United Kingdom, Cropton | Q25: 45336.611 | R25: PT2M | U25: freshwater wetland ecosystem [ENVO_00000243] | V25: shrub layer [ENVO:01000336] | W25: fresh water [ENVO:00002011] | X25: 0 | Y25: Water sample (2L bottle dippled into small stream in 3 distinct areas within 3m of the point) | Z25: water bottle | AA25: 2000 | AB25: mL | AC25: 10 | AD25: none | AE25: PT3H | AP25: 0.45 | AS25: cellulose ester | AT25: Whatman | AY25: -18 | BF25: enzymatic | BG25: column-based | BH25: https://mbmg.pensoft.net/article/24556/ | BI25: Mu DNA | BJ25: https://mbmg.pensoft.net/article/24556/ | BK25: 0 | BQ25: 1 | BS25: 12S-V5 | BU25: Dry, cloudy
A26: 0211 | B26: sample | E26: =_xlfn.CONCAT(projectMetadata!$D$8,"_",sampleMetadata!A26) -> CROP_2024_0211 | F26: =LEFT(A26,9) -> 0211 | G26: =F26 -> 0211 | H26: CROP_02EB, CROP_02FB, NEG05, POS05 | J26: -0.819925 | K26: 54.304091 | P26: United Kingdom, Cropton | Q26: 45336.542 | R26: PT2M | U26: freshwater wetland ecosystem [ENVO_00000243] | V26: shrub layer [ENVO:01000336] | W26: fresh water [ENVO:00002011] | X26: 0 | Y26: Water sample (2L bottle dippled into small stream in 3 distinct areas within 3m of the point) | Z26: water bottle | AA26: 2000 | AB26: mL | AC26: 10 | AD26: none | AE26: PT3H | AP26: 0.45 | AS26: cellulose ester | AT26: Whatman | AY26: -18 | BF26: enzymatic | BG26: column-based | BH26: https://mbmg.pensoft.net/article/24556/ | BI26: Mu DNA | BJ26: https://mbmg.pensoft.net/article/24556/ | BK26: 0 | BQ26: 1 | BS26: 12S-V5 | BU26: Overcast
A27: 0212 | B27: sample | E27: =_xlfn.CONCAT(projectMetadata!$D$8,"_",sampleMetadata!A27) -> CROP_2024_0212 | F27: =LEFT(A27,9) -> 0212 | G27: =F27 -> 0212 | H27: CROP_02EB, CROP_02FB, NEG05, POS05 | J27: -0.829613 | K27: 54.303712 | P27: United Kingdom, Cropton | Q27: 45336.531 | R27: PT2M | U27: freshwater wetland ecosystem [ENVO_00000243] | V27: shrub layer [ENVO:01000336] | W27: fresh water [ENVO:00002011] | X27: 0 | Y27: Water sample (2L bottle dippled into small stream in 3 distinct areas within 3m of the point) | Z27: water bottle | AA27: 2000 | AB27: mL | AC27: 10 | AD27: none | AE27: PT3H | AP27: 0.45 | AS27: cellulose ester | AT27: Whatman | AY27: -18 | BF27: enzymatic | BG27: column-based | BH27: https://mbmg.pensoft.net/article/24556/ | BI27: Mu DNA | BJ27: https://mbmg.pensoft.net/article/24556/ | BK27: 0 | BQ27: 1 | BS27: 12S-V5 | BU27: Overcast
... A29: 0214 | B29: sample | E29: =_xlfn.CONCAT(projectMetadata!$D$8,"_",sampleMetadata!A29) -> CROP_2024_0214 | F29: =LEFT(A29,9) -> 0214 | G29: =F29 -> 0214 | H29: CROP_02EB, CROP_02FB, NEG05, POS05 | J29: -0.845707 | K29: 54.295705 | P29: United Kingdom, Cropton | Q29: 45336.472 | R29: PT2M | U29: freshwater wetland ecosystem [ENVO_00000243] | V29: shrub layer [ENVO:01000336] | W29: fresh water [ENVO:00002011] | X29: 0 | Y29: Water sample (2L bottle dippled into small stream in 3 distinct areas within 3m of the point) | Z29: water bottle | AA29: 2000 | AB29: mL | AC29: 10 | AD29: none | AE29: PT3H | AP29: 0.45 | AS29: cellulose ester | AT29: Whatman | AY29: -18 | BF29: enzymatic | BG29: column-based | BH29: https://mbmg.pensoft.net/article/24556/ | BI29: Mu DNA | BJ29: https://mbmg.pensoft.net/article/24556/ | BK29: 0 | BQ29: 1 | BS29: 12S-V5 | BU29: Overcast
A30: 02EB | B30: negative control | C30: extraction negative | E30: =_xlfn.CONCAT(projectMetadata!$D$8,"_",sampleMetadata!A30) -> CROP_2024_02EB | F30: =LEFT(A30,9) -> 02EB | G30: =F30 -> 02EB | BF30: enzymatic | BG30: column-based | BH30: https://mbmg.pensoft.net/article/24556/ | BI30: Mu DNA | BJ30: https://mbmg.pensoft.net/article/24556/ | BK30: 0 | BQ30: 1 | BS30: 12S-V5 | BU30: Overcast
A31: 02FB | B31: negative control | C31: field negative | E31: =_xlfn.CONCAT(projectMetadata!$D$8,"_",sampleMetadata!A31) -> CROP_2024_02FB | F31: =LEFT(A31,9) -> 02FB | G31: =F31 -> 02FB | AP31: 0.45 | AS31: cellulose ester | AT31: Whatman | AY31: -18 | BF31: enzymatic | BG31: column-based | BH31: https://mbmg.pensoft.net/article/24556/ | BI31: Mu DNA | BJ31: https://mbmg.pensoft.net/article/24556/ | BK31: 0 | BQ31: 1 | BS31: 12S-V5 | BU31: Overcast
A32: 0301 | B32: sample | E32: =_xlfn.CONCAT(projectMetadata!$D$8,"_",sampleMetadata!A32) -> CROP_2024_0301 | F32: =LEFT(A32,9) -> 0301 | G32: =F32 -> 0301 | H32: CROP_03EB, CROP_03FB, NEG02, POS02 | J32: -0.81100264 | K32: 54.305806 | P32: United Kingdom, Cropton | Q32: 45376.535 | R32: PT2M | U32: freshwater wetland ecosystem [ENVO_00000243] | V32: shrub layer [ENVO:01000336] | W32: fresh water [ENVO:00002011] | X32: 0 | Y32: Water sample (2L bottle dippled into small stream in 3 distinct areas within 3m of the point) | Z32: water bottle | AA32: 2000 | AB32: mL | AC32: 10 | AD32: none | AE32: PT3H | AP32: 0.45 | AS32: cellulose ester | AT32: Whatman | AY32: -18 | BF32: enzymatic | BG32: column-based | BH32: https://mbmg.pensoft.net/article/24556/ | BI32: Mu DNA | BJ32: https://mbmg.pensoft.net/article/24556/ | BK32: 0 | BQ32: 1 | BS32: 12S-V5 | BU32: Overcast
A33: 0302 | B33: sample | E33: =_xlfn.CONCAT(projectMetadata!$D$8,"_",sampleMetadata!A33) -> CROP_2024_0302 | F33: =LEFT(A33,9) -> 0302 | G33: =F33 -> 0302 | H33: CROP_03EB, CROP_03FB, NEG02, POS02 | J33: -0.80960976 | K33: 54.306325 | P33: United Kingdom, Cropton | Q33: 45376.528 | R33: PT2M | U33: freshwater wetland ecosystem [ENVO_00000243] | V33: shrub layer [ENVO:01000336] | W33: fresh water [ENVO:00002011] | X33: 0 | Y33: Water sample (2L bottle dippled into small stream in 3 distinct areas within 3m of the point) | Z33: water bottle | AA33: 2000 | AB33: mL | AC33: 10 | AD33: none | AE33: PT3H | AP33: 0.45 | AS33: cellulose ester | AT33: Whatman | AY33: -18 | BF33: enzymatic | BG33: column-based | BH33: https://mbmg.pensoft.net/article/24556/ | BI33: Mu DNA | BJ33: https://mbmg.pensoft.net/article/24556/ | BK33: 0 | BQ33: 1 | BS33: 12S-V5 | BU33: Sunny
A34: 0303 | B34: sample | E34: =_xlfn.CONCAT(projectMetadata!$D$8,"_",sampleMetadata!A34) -> CROP_2024_0303 | F34: =LEFT(A34,9) -> 0303 | G34: =F34 -> 0303 | H34: CROP_03EB, CROP_03FB, NEG02, POS02 | J34: -0.81187299 | K34: 54.305987 | P34: United Kingdom, Cropton | Q34: 45376.517 | R34: PT2M | U34: freshwater wetland ecosystem [ENVO_00000243] | V34: shrub layer [ENVO:01000336] | W34: fresh water [ENVO:00002011] | X34: 0 | Y34: Water sample (2L bottle dippled into small stream in 3 distinct areas within 3m of the point) | Z34: water bottle | AA34: 2000 | AB34: mL | AC34: 10 | AD34: none | AE34: PT3H | AP34: 0.45 | AS34: cellulose ester | AT34: Whatman | AY34: -18 | BF34: enzymatic | BG34: column-based | BH34: https://mbmg.pensoft.net/article/24556/ | BI34: Mu DNA | BJ34: https://mbmg.pensoft.net/article/24556/ | BK34: 0 | BQ34: 1 | BS34: 12S-V5 | BU34: Sunny
A35: 0304 | B35: sample | E35: =_xlfn.CONCAT(projectMetadata!$D$8,"_",sampleMetadata!A35) -> CROP_2024_0304 | F35: =LEFT(A35,9) -> 0304 | G35: =F35 -> 0304 | H35: CROP_03EB, CROP_03FB, NEG02, POS02 | J35: -0.8115562 | K35: 54.305646 | P35: United Kingdom, Cropton | Q35: 45376.514 | R35: PT2M | U35: freshwater wetland ecosystem [ENVO_00000243] | V35: shrub layer [ENVO:01000336] | W35: fresh water [ENVO:00002011] | X35: 0 | Y35: Water sample (2L bottle dippled into small stream in 3 distinct areas within 3m of the point) | Z35: water bottle | AA35: 2000 | AB35: mL | AC35: 10 | AD35: none | AE35: PT3H | AP35: 0.45 | AS35: cellulose ester | AT35: Whatman | AY35: -18 | BF35: enzymatic | BG35: column-based | BH35: https://mbmg.pensoft.net/article/24556/ | BI35: Mu DNA | BJ35: https://mbmg.pensoft.net/article/24556/ | BK35: 0 | BQ35: 1 | BS35: 12S-V5 | BU35: Sunny
A36: 0305 | B36: sample | E36: =_xlfn.CONCAT(projectMetadata!$D$8,"_",sampleMetadata!A36) -> CROP_2024_0305 | F36: =LEFT(A36,9) -> 0305 | G36: =F36 -> 0305 | H36: CROP_03EB, CROP_03FB, NEG02, POS02 | J36: -0.81322506 | K36: 54.30521 | P36: United Kingdom, Cropton | Q36: 45376.5 | R36: PT2M | U36: freshwater wetland ecosystem [ENVO_00000243] | V36: shrub layer [ENVO:01000336] | W36: fresh water [ENVO:00002011] | X36: 0 | Y36: Water sample (2L bottle dippled into small stream in 3 distinct areas within 3m of the point) | Z36: water bottle | AA36: 2000 | AB36: mL | AC36: 10 | AD36: none | AE36: PT3H | AP36: 0.45 | AS36: cellulose ester | AT36: Whatman | AY36: -18 | BF36: enzymatic | BG36: column-based | BH36: https://mbmg.pensoft.net/article/24556/ | BI36: Mu DNA | BJ36: https://mbmg.pensoft.net/article/24556/ | BK36: 0 | BQ36: 1 | BS36: 12S-V5 | BU36: Sunny
A37: 0306 | B37: sample | E37: =_xlfn.CONCAT(projectMetadata!$D$8,"_",sampleMetadata!A37) -> CROP_2024_0306 | F37: =LEFT(A37,9) -> 0306 | G37: =F37 -> 0306 | H37: CROP_03EB, CROP_03FB, NEG02, POS02 | J37: -0.81573976 | K37: 54.304996 | P37: United Kingdom, Cropton | Q37: 45376.497 | R37: PT2M | U37: freshwater wetland ecosystem [ENVO_00000243] | V37: shrub layer [ENVO:01000336] | W37: fresh water [ENVO:00002011] | X37: 0 | Y37: Water sample (2L bottle dippled into small stream in 3 distinct areas within 3m of the point) | Z37: water bottle | AA37: 2000 | AB37: mL | AC37: 10 | AD37: none | AE37: PT3H | AP37: 0.45 | AS37: cellulose ester | AT37: Whatman | AY37: -18 | BF37: enzymatic | BG37: column-based | BH37: https://mbmg.pensoft.net/article/24556/ | BI37: Mu DNA | BJ37: https://mbmg.pensoft.net/article/24556/ | BK37: 0 | BQ37: 1 | BS37: 12S-V5 | BU37: Sunny
A38: 0307 | B38: sample | E38: =_xlfn.CONCAT(projectMetadata!$D$8,"_",sampleMetadata!A38) -> CROP_2024_0307 | F38: =LEFT(A38,9) -> 0307 | G38: =F38 -> 0307 | H38: CROP_03EB, CROP_03FB, NEG02, POS02 | J38: -0.81746413 | K38: 54.304684 | P38: United Kingdom, Cropton | Q38: 45376.486 | R38: PT2M | U38: freshwater wetland ecosystem [ENVO_00000243] | V38: shrub layer [ENVO:01000336] | W38: fresh water [ENVO:00002011] | X38: 0 | Y38: Water sample (2L bottle dippled into small stream in 3 distinct areas within 3m of the point) | Z38: water bottle | AA38: 2000 | AB38: mL | AC38: 10 | AD38: none | AE38: PT3H | AP38: 0.45 | AS38: cellulose ester | AT38: Whatman | AY38: -18 | BF38: enzymatic | BG38: column-based | BH38: https://mbmg.pensoft.net/article/24556/ | BI38: Mu DNA | BJ38: https://mbmg.pensoft.net/article/24556/ | BK38: 0 | BQ38: 1 | BS38: 12S-V5 | BU38: Sunny
A39: 0308 | B39: sample | E39: =_xlfn.CONCAT(projectMetadata!$D$8,"_",sampleMetadata!A39) -> CROP_2024_0308 | F39: =LEFT(A39,9) -> 0308 | G39: =F39 -> 0308 | H39: CROP_03EB, CROP_03FB, NEG02, POS02 | J39: -0.81789849 | K39: 54.304594 | P39: United Kingdom, Cropton | Q39: 45376.483 | R39: PT2M | U39: freshwater wetland ecosystem [ENVO_00000243] | V39: shrub layer [ENVO:01000336] | W39: fresh water [ENVO:00002011] | X39: 0 | Y39: Water sample (2L bottle dippled into small stream in 3 distinct areas within 3m of the point) | Z39: water bottle | AA39: 2000 | AB39: mL | AC39: 10 | AD39: none | AE39: PT3H | AP39: 0.45 | AS39: cellulose ester | AT39: Whatman | AY39: -18 | BF39: enzymatic | BG39: column-based | BH39: https://mbmg.pensoft.net/article/24556/ | BI39: Mu DNA | BJ39: https://mbmg.pensoft.net/article/24556/ | BK39: 0 | BQ39: 1 | BS39: 12S-V5 | BU39: Drizzle
A40: 0309 | B40: sample | E40: =_xlfn.CONCAT(projectMetadata!$D$8,"_",sampleMetadata!A40) -> CROP_2024_0309 | F40: =LEFT(A40,9) -> 0309 | G40: =F40 -> 0309 | H40: CROP_03EB, CROP_03FB, NEG02, POS02 | J40: -0.81844389 | K40: 54.30436 | P40: United Kingdom, Cropton | Q40: 45376.476 | R40: PT2M | U40: freshwater wetland ecosystem [ENVO_00000243] | V40: shrub layer [ENVO:01000336] | W40: fresh water [ENVO:00002011] | X40: 0 | Y40: Water sample (2L bottle dippled into small stream in 3 distinct areas within 3m of the point) | Z40: water bottle | AA40: 2000 | AB40: mL | AC40: 10 | AD40: none | AE40: PT3H | AP40: 0.45 | AS40: cellulose ester | AT40: Whatman | AY40: -18 | BF40: enzymatic | BG40: column-based | BH40: https://mbmg.pensoft.net/article/24556/ | BI40: Mu DNA | BJ40: https://mbmg.pensoft.net/article/24556/ | BK40: 0 | BQ40: 1 | BS40: 12S-V5 | BU40: Drizzle
A41: 0310 | B41: sample | E41: =_xlfn.CONCAT(projectMetadata!$D$8,"_",sampleMetadata!A41) -> CROP_2024_0310 | F41: =LEFT(A41,9) -> 0310 | G41: =F41 -> 0310 | H41: CROP_03EB, CROP_03FB, NEG02, POS02 | J41: -0.81895989 | K41: 54.304236 | P41: United Kingdom, Cropton | Q41: 45376.469 | R41: PT2M | U41: freshwater wetland ecosystem [ENVO_00000243] | V41: shrub layer [ENVO:01000336] | W41: fresh water [ENVO:00002011] | X41: 0 | Y41: Water sample (2L bottle dippled into small stream in 3 distinct areas within 3m of the point) | Z41: water bottle | AA41: 2000 | AB41: mL | AC41: 10 | AD41: none | AE41: PT3H | AP41: 0.45 | AS41: cellulose ester | AT41: Whatman | AY41: -18 | BF41: enzymatic | BG41: column-based | BH41: https://mbmg.pensoft.net/article/24556/ | BI41: Mu DNA | BJ41: https://mbmg.pensoft.net/article/24556/ | BK41: 0 | BQ41: 1 | BS41: 12S-V5 | BU41: Drizzle
...

Sheet ampData
A1: # requirement_level_code | B1: M | C1: M | D1: M | E1: M | F1: O | G1: R | H1: R | I1: R | J1: R | K1: R
A2: # section | B2: PCR | C2: PCR | D2: PCR | E2: Targeted assay detection | F2: Targeted assay detection | G2: Targeted assay detection | H2: Targeted assay detection | I2: Targeted assay detection | J2: Targeted assay detection | K2: Targeted assay detection
A3: samp_name | B3: technical_rep_id | C3: assay_name | D3: pcr_plate_id | E3: quantificationCycle | F3: rfu | G3: estimatedNumberOfCopies_method | H3: estimatedNumberOfCopies | I3: estimatedNumberOfCopies_unit | J3: estimatedNumberOfCopies_error | K3: estimatedNumberOfCopies_error_type
A4: 0101 | B4: 1 | C4: 12S-V5
A5: 0102 | B5: 1 | C5: 12S-V5
A6: 0103 | B6: 1 | C6: 12S-V5
A7: 0104 | B7: 1 | C7: 12S-V5
A8: 0105 | B8: 1 | C8: 12S-V5
A9: 0106 | B9: 1 | C9: 12S-V5
A10: 0107 | B10: 1 | C10: 12S-V5
A11: 0108 | B11: 1 | C11: 12S-V5
A12: 0109 | B12: 1 | C12: 12S-V5
A13: 0110 | B13: 1 | C13: 12S-V5
A14: 01EB | B14: 1 | C14: 12S-V5
A15: 01FB | B15: 1 | C15: 12S-V5
... A192: POS10 | B192: 1 | C192: 12S-V5

Sheet stdData
A1: # requirement_level_code | B1: M | C1: M | D1: M | E1: M | F1: M | G1: M | H1: O | I1: HR | J1: HR | K1: R | L1: R
A2: # section | B2: PCR | C2: PCR | D2: PCR | E2: Targeted assay detection | F2: Targeted assay detection | G2: Targeted assay detection | H2: Targeted assay detection | I2: Targeted assay detection | J2: Targeted assay detection | K2: Targeted assay detection | L2: Targeted assay detection
A3: samp_name | B3: technical_rep_id | C3: assay_name | D3: pcr_plate_id | E3: std_conc | F3: std_conc_unit | G3: quantificationCycle | H3: rfu | I3: efficiency | J3: r2 | K3: slope | L3: intercept
A4: 0101 | B4: 1 | C4: 12S-V5
A5: 0102 | B5: 1 | C5: 12S-V5
A6: 0103 | B6: 1 | C6: 12S-V5
A7: 0104 | B7: 1 | C7: 12S-V5
A8: 0105 | B8: 1 | C8: 12S-V5
A9: 0106 | B9: 1 | C9: 12S-V5
A10: 0107 | B10: 1 | C10: 12S-V5
A11: 0108 | B11: 1 | C11: 12S-V5
A12: 0109 | B12: 1 | C12: 12S-V5
A13: 0110 | B13: 1 | C13: 12S-V5
A14: 01EB | B14: 1 | C14: 12S-V5
A15: 01FB | B15: 1 | C15: 12S-V5
... A192: POS10 | B192: 1 | C192: 12S-V5

Sheet eLowQuantData
A1: # requirement_level_code | B1: HR | C1: R | D1: R | E1: R | F1: R
A2: # section | B2: Targeted assay detection | C2: Targeted assay detection | D2: Targeted assay detection | E2: Targeted assay detection | F2: Targeted assay detection
A3: assay_name | B3: num_detect | C3: estimatedNumberOfCopies | D3: estimatedNumberOfCopies_unit | E3: estimatedNumberOfCopies_error | F3: estimatedNumberOfCopies_error_type

Sheet experimentRunMetadata
A1: # requirement_level_code | B1: M | C1: M | D1: M | E1: M | F1: R | G1: R | H1: R | I1: R | J1: O | K1: O | L1: R | M1: R | N1: R | O1: R | P1: R | Q1: R | R1: R | S1: R | T1: R
A2: # section | B2: PCR | C2: PCR | D2: Library preparation sequencing | E2: Library preparation sequencing | F2: Library preparation sequencing | G2: Library preparation sequencing | H2: Library preparation sequencing | I2: Library preparation sequencing | J2: Library preparation sequencing | K2: Library preparation sequencing | L2: Library preparation sequencing | M2: Library preparation sequencing | N2: Library preparation sequencing | O2: Library preparation sequencing | P2: Library preparation sequencing | Q2: Bioinformatics | R2: Bioinformatics | S2: Bioinformatics | T2: Bioinformatics
A3: samp_name | B3: assay_name | C3: pcr_plate_id | D3: lib_id | E3: seq_run_id | F3: lib_conc | G3: lib_conc_unit | H3: lib_conc_meth | I3: phix_perc | J3: mid_forward | K3: mid_reverse | L3: filename | M3: filename2 | N3: checksum_filename | O3: checksum_filename2 | P3: associatedSequences | Q3: input_read_count | R3: output_read_count | S3: output_otu_num | T3: otu_num_tax_assigned
A4: 0101 | B4: 12S-V5 | D4: Lib1 | E4: run18092024 | F4: 4 | G4: nM | H4: Qubit 3.0 Fluorometer | I4: 10 | L4: CROP_0101.R1.fastq.gz | M4: CROP_0101.R2.fastq.gz | R4: 25188 | T4: 23
A5: 0102 | B5: 12S-V5 | D5: Lib1 | E5: run18092024 | F5: 4 | G5: nM | H5: Qubit 3.0 Fluorometer | I5: 10 | L5: CROP_0102.R1.fastq.gz | M5: CROP_0102.R2.fastq.gz | R5: 26540 | T5: 24
A6: 0103 | B6: 12S-V5 | D6: Lib1 | E6: run18092024 | F6: 4 | G6: nM | H6: Qubit 3.0 Fluorometer | I6: 10 | L6: CROP_0103.R1.fastq.gz | M6: CROP_0103.R2.fastq.gz | R6: 13083 | T6: 17
A7: 0104 | B7: 12S-V5 | D7: Lib1 | E7: run18092024 | F7: 4 | G7: nM | H7: Qubit 3.0 Fluorometer | I7: 10 | L7: CROP_0104.R1.fastq.gz | M7: CROP_0104.R2.fastq.gz | R7: 29446 | T7: 22
A8: 0105 | B8: 12S-V5 | D8: Lib1 | E8: run18092024 | F8: 4 | G8: nM | H8: Qubit 3.0 Fluorometer | I8: 10 | L8: CROP_0105.R1.fastq.gz | M8: CROP_0105.R2.fastq.gz | R8: 33286 | T8: 25
A9: 0106 | B9: 12S-V5 | D9: Lib1 | E9: run18092024 | F9: 4 | G9: nM | H9: Qubit 3.0 Fluorometer | I9: 10 | L9: CROP_0106.R1.fastq.gz | M9: CROP_0106.R2.fastq.gz | R9: 28460 | T9: 25
A10: 0107 | B10: 12S-V5 | D10: Lib1 | E10: run18092024 | F10: 4 | G10: nM | H10: Qubit 3.0 Fluorometer | I10: 10 | L10: CROP_0107.R1.fastq.gz | M10: CROP_0107.R2.fastq.gz | R10: 27482 | T10: 20
A11: 0108 | B11: 12S-V5 | D11: Lib1 | E11: run18092024 | F11: 4 | G11: nM | H11: Qubit 3.0 Fluorometer | I11: 10 | L11: CROP_0108.R1.fastq.gz | M11: CROP_0108.R2.fastq.gz | R11: 27885 | T11: 20
A12: 0109 | B12: 12S-V5 | D12: Lib1 | E12: run18092024 | F12: 4 | G12: nM | H12: Qubit 3.0 Fluorometer | I12: 10 | L12: CROP_0109.R1.fastq.gz | M12: CROP_0109.R2.fastq.gz | R12: 42599 | T12: 20
A13: 0110 | B13: 12S-V5 | D13: Lib1 | E13: run18092024 | F13: 4 | G13: nM | H13: Qubit 3.0 Fluorometer | I13: 10 | L13: CROP_0110.R1.fastq.gz | M13: CROP_0110.R2.fastq.gz | R13: 39713 | T13: 21
A14: 01EB | B14: 12S-V5 | D14: Lib1 | E14: run18092024 | F14: 4 | G14: nM | H14: Qubit 3.0 Fluorometer | I14: 10 | L14: CROP_01EB.R1.fastq.gz | M14: CROP_01EB.R2.fastq.gz | R14: 5862 | T14: 3
A15: 01FB | B15: 12S-V5 | D15: Lib1 | E15: run18092024 | F15: 4 | G15: nM | H15: Qubit 3.0 Fluorometer | I15: 10 | L15: CROP_01FB.R1.fastq.gz | M15: CROP_01FB.R2.fastq.gz | R15: 6 | T15: 1
... A192: POS10 | B192: 12S-V5 | D192: Lib11 | E192: run18092024 | F192: 4 | G192: nM | H192: Qubit 3.0 Fluorometer | I192: 10 | L192: CROP_POS10.R1.fastq.gz | M192: CROP_POS10.R2.fastq.gz | R192: 34146 | T192: 7

Sheet taxaRaw
A1: # requirement_level_code | B1: M | C1: R | D1: R | E1: R | F1: R | G1: R | H1: R | I1: R | J1: HR | K1: R | L1: HR | M1: HR | N1: HR | O1: O | P1: R | Q1: R | R1: R | S1: R | T1: R | U1: O
A2: # section | B2: OTU/ASV | C2: OTU/ASV | D2: OTU/ASV | E2: OTU/ASV | F2: OTU/ASV | G2: OTU/ASV | H2: OTU/ASV | I2: OTU/ASV | J2: OTU/ASV | K2: OTU/ASV | L2: OTU/ASV | M2: OTU/ASV | N2: OTU/ASV | O2: OTU/ASV | P2: OTU/ASV | Q2: OTU/ASV | R2: OTU/ASV | S2: OTU/ASV | T2: OTU/ASV | U2: OTU/ASV
A3: seq_id | B3: dna_sequence | C3: kingdom | D3: phylum | E3: class | F3: order | G3: family | H3: genus | I3: specificEpithet | J3: scientificName | K3: scientificNameAuthorship | L3: taxonRank | M3: taxonID | N3: taxonID_db | O3: verbatimIdentification | P3: accession_id | Q3: accession_id_ref_db | R3: percent_match | S3: percent_query_cover | T3: confidence_score | U3: identificationRemarks

Sheet taxaFinal
A1: # requirement_level_code | B1: M | C1: R | D1: R | E1: R | F1: R | G1: R | H1: R | I1: R | J1: HR | K1: R | L1: HR | M1: HR | N1: HR | O1: O | P1: R | Q1: R | R1: R | S1: R | T1: R | U1: O
A2: # section | B2: OTU/ASV | C2: OTU/ASV | D2: OTU/ASV | E2: OTU/ASV | F2: OTU/ASV | G2: OTU/ASV | H2: OTU/ASV | I2: OTU/ASV | J2: OTU/ASV | K2: OTU/ASV | L2: OTU/ASV | M2: OTU/ASV | N2: OTU/ASV | O2: OTU/ASV | P2: OTU/ASV | Q2: OTU/ASV | R2: OTU/ASV | S2: OTU/ASV | T2: OTU/ASV | U2: OTU/ASV
A3: seq_id | B3: dna_sequence | C3: kingdom | D3: phylum | E3: class | F3: order | G3: family | H3: genus | I3: specificEpithet | J3: scientificName | K3: scientificNameAuthorship | L3: taxonRank | M3: taxonID | N3: taxonID_db | O3: verbatimIdentification | P3: accession_id | Q3: accession_id_ref_db | R3: percent_match | S3: percent_query_cover | T3: confidence_score | U3: identificationRemarks
